Workbook

Sheet Лист2
A3: Названия строк | B3: Сумма по полю purchase_amount | F3: Месяц | G3: с покупкой | H3: без покупки
A4: 1 | B4: 33009.18 | F4: январь | G4: 325 | H4: 569
A5: 2 | B5: 26399.06 | F5: февраль | G5: 281 | H5: 483
A6: 3 | B6: 28658.52 | F6: март | G6: 316 | H6: 526
A7: 4 | B7: 28792.18 | F7: апрель | G7: 304 | H7: 546
A8: 5 | B8: 30223 | F8: май | G8: 316 | H8: 550
A9: 6 | B9: 27556.91 | F9: июнь | G9: 278 | H9: 506
A10: Общий итог | B10: 174638.85
F11: Месяц | G11: сумма продажи
F12: январь | G12: 33009.18
A13: purchase_amount | B13: (несколько элементов) | F13: февраль | G13: 26399.06
F14: март | G14: 28658.52
A15: Названия строк | B15: Количество по полю purchase_amount | F15: апрель | G15: 28792.18
A16: 1 | B16: 325 | F16: май | G16: 30223
A17: 2 | B17: 281 | F17: июнь | G17: 27556.91
A18: 3 | B18: 316
A19: 4 | B19: 304
A20: 5 | B20: 316
A21: 6 | B21: 278
A22: Общий итог | B22: 1820

Sheet Лист5
A3: Названия строк | B3: Сумма по полю purchase_amount
A4: Email | B4: 26272.25
A5: Organic | B5: 74693.91
A6: PaidAds | B6: 53425.14
A7: Referral | B7: 20247.55
A8: Общий итог | B8: 174638.85

Sheet datasetExcel
A1: customer_id | B1: date | C1: age | D1: gender | E1: region | F1: traffic_source | G1: campaign | H1: time_on_site_s | I1: pages_visited | J1: converted | K1: purchase_amount | L1: num_items | M1: delivery_time_days | N1: satisfaction | O1: Месяц | R1: Характериситка | S1: =K1 -> purchase_amount | T1: =H1 -> time_on_site_s | U1: =I1 -> pages_visited | V1: =M1 -> delivery_time_days | W1: =N1 -> satisfaction
A2: 2295 | B2: 45658 | C2: 30 | D2: Male | E2: South | F2: Organic | H2: 373.7 | I2: 8 | J2: 1 | K2: 43 | L2: 5 | M2: 9 | N2: 4 | O2: =MONTH(B2) -> 1 | R2: Диапазон от: | S2: =MIN(datasetExcel!K:K) -> 0 | T2: =MIN(datasetExcel!H:H) -> 1 | U2: =MIN(datasetExcel!I:I) -> 1 | V2: =MIN(datasetExcel!M:M) -> 0 | W2: =MIN(datasetExcel!N:N) -> 2
A3: 2903 | B3: 45658 | C3: 55 | D3: Female | E3: South | F3: PaidAds | G3: CAMP3 | H3: 1407.9 | I3: 3 | J3: 1 | K3: 294 | L3: 3 | M3: 12 | N3: 5 | O3: =MONTH(B3) -> 1 | R3: Диапазон до: | S3: =MAX(datasetExcel!K:K) -> 1419.3 | T3: =MAX(datasetExcel!H:H) -> 2235.3 | U3: =MAX(datasetExcel!I:I) -> 18 | V3: =MAX(datasetExcel!M:M) -> 15 | W3: =MAX(datasetExcel!N:N) -> 5
A4: 1922 | B4: 45658 | C4: 21 | D4: Female | E4: North | F4: Referral | H4: 493 | I4: 5 | J4: 1 | K4: 81.55 | L4: 4 | M4: 14 | N4: 4 | O4: =MONTH(B4) -> 1 | R4: Среднее | S4: =AVERAGE(datasetExcel!K:K) -> 34.92777 | T4: =AVERAGE(datasetExcel!H:H) -> 361.8725 | U4: =AVERAGE(datasetExcel!I:I) -> 5.9884 | V4: =AVERAGE(datasetExcel!M:M) -> 2.8718 | W4: =AVERAGE(datasetExcel!N:N) -> 4.0950549
A5: 3627 | B5: 45658 | C5: 44 | D5: Male | E5: South | F5: Organic | H5: 784.2 | I5: 13 | J5: 1 | K5: 60.45 | L5: 2 | M5: 5 | N5: 3 | O5: =MONTH(B5) -> 1 | R5: Медиана | S5: =MEDIAN(datasetExcel!K:K) -> 0 | T5: =MEDIAN(datasetExcel!H:H) -> 305.45 | U5: =MEDIAN(datasetExcel!I:I) -> 6 | V5: =MEDIAN(datasetExcel!M:M) -> 0 | W5: =MEDIAN(datasetExcel!N:N) -> 4
A6: 2605 | B6: 45658 | C6: 22 | D6: Male | E6: East | F6: Organic | H6: 1090.9 | I6: 9 | J6: 1 | K6: 45.87 | L6: 4 | M6: 1 | N6: 4 | O6: =MONTH(B6) -> 1 | R6: Дисперсия | S6: =VARP(datasetExcel!K:K) -> 7613.5259 | T6: =VARP(datasetExcel!H:H) -> 65269.403 | U6: =VARP(datasetExcel!I:I) -> 5.0626654 | V6: =VARP(datasetExcel!M:M) -> 20.924165 | W6: =VARP(datasetExcel!N:N) -> 0.41459093
A7: 3218 | B7: 45658 | C7: 32 | D7: Male | E7: North | F7: Email | H7: 1417.7 | I7: 6 | J7: 1 | K7: 41.92 | L7: 3 | M7: 13 | N7: 5 | O7: =MONTH(B7) -> 1 | R7: Коэффицент вариации | S7: =STDEV(datasetExcel!K:K)/AVERAGE(datasetExcel!K:K) -> 2.4984202 | T7: =STDEV(datasetExcel!H:H)/AVERAGE(datasetExcel!H:H) -> 0.70606173 | U7: =STDEV(datasetExcel!I:I)/AVERAGE(datasetExcel!I:I) -> 0.37577012 | V7: =STDEV(datasetExcel!M:M)/AVERAGE(datasetExcel!M:M) -> 1.5929909 | W7: =STDEV(datasetExcel!N:N)/AVERAGE(datasetExcel!N:N) -> 0.15727855
A8: 822 | B8: 45658 | C8: 27 | D8: Male | E8: East | F8: Email | H8: 253 | I8: 4 | J8: 1 | K8: 32.4 | L8: 3 | M8: 9 | N8: 5 | O8: =MONTH(B8) -> 1
A9: 73 | B9: 45658 | C9: 25 | D9: Female | E9: South | F9: Email | H9: 276.1 | I9: 9 | J9: 1 | K9: 23.42 | L9: 2 | M9: 4 | N9: 4 | O9: =MONTH(B9) -> 1
A10: 1902 | B10: 45658 | C10: 18 | D10: Female | E10: West | F10: Organic | H10: 436 | I10: 1 | J10: 1 | K10: 23.34 | L10: 5 | M10: 8 | N10: 5 | O10: =MONTH(B10) -> 1
A11: 4979 | B11: 45658 | C11: 67 | D11: Male | E11: East | F11: Organic | H11: 198.9 | I11: 4 | J11: 1 | K11: 20.94 | L11: 7 | M11: 9 | N11: 5 | O11: =MONTH(B11) -> 1
A12: 1427 | B12: 45658 | C12: 23 | D12: Male | E12: North | F12: Organic | H12: 80.3 | I12: 6 | J12: 1 | K12: 20.31 | L12: 4 | M12: 8 | N12: 5 | O12: =MONTH(B12) -> 1
A13: 2633 | B13: 45658 | C13: 36 | D13: Female | E13: South | F13: PaidAds | G13: CAMP5 | H13: 483.7 | I13: 3 | J13: 0 | K13: 0 | L13: 0 | M13: 0 | O13: =MONTH(B13) -> 1
A14: 4777 | B14: 45658 | C14: 55 | D14: Male | E14: South | F14: Organic | H14: 466.4 | I14: 7 | J14: 0 | K14: 0 | L14: 0 | M14: 0 | O14: =MONTH(B14) -> 1
A15: 4412 | B15: 45658 | C15: 58 | D15: Male | E15: South | F15: PaidAds | G15: CAMP3 | H15: 454 | I15: 3 | J15: 0 | K15: 0 | L15: 0 | M15: 0 | O15: =MONTH(B15) -> 1
A16: 2328 | B16: 45658 | C16: 39 | D16: Female | E16: East | F16: Organic | H16: 180.4 | I16: 11 | J16: 0 | K16: 0 | L16: 0 | M16: 0 | O16: =MONTH(B16) -> 1
A17: 4152 | B17: 45658 | C17: 45 | D17: Male | E17: North | F17: Organic | H17: 168.2 | I17: 5 | J17: 0 | K17: 0 | L17: 0 | M17: 0 | O17: =MONTH(B17) -> 1
A18: 4130 | B18: 45658 | C18: 57 | D18: Male | E18: West | F18: PaidAds | G18: CAMP2 | H18: 131 | I18: 7 | J18: 0 | K18: 0 | L18: 0 | M18: 0 | O18: =MONTH(B18) -> 1
A19: 2612 | B19: 45658 | C19: 29 | D19: Other | E19: East | F19: Email | H19: 128.2 | I19: 4 | J19: 0 | K19: 0 | L19: 0 | M19: 0 | O19: =MONTH(B19) -> 1
A20: 2912 | B20: 45658 | C20: 21 | D20: Female | E20: East | F20: Organic | H20: 114.4 | I20: 2 | J20: 0 | K20: 0 | L20: 0 | M20: 0 | O20: =MONTH(B20) -> 1
A21: 2715 | B21: 45658 | C21: 25 | D21: Male | E21: East | F21: Organic | H21: 88.4 | I21: 8 | J21: 0 | K21: 0 | L21: 0 | M21: 0 | O21: =MONTH(B21) -> 1
A22: 209 | B22: 45658 | C22: 25 | D22: Female | E22: East | F22: Organic | H22: 88.2 | I22: 8 | J22: 0 | K22: 0 | L22: 0 | M22: 0 | O22: =MONTH(B22) -> 1
A23: 4726 | B23: 45658 | C23: 43 | D23: Male | E23: East | F23: PaidAds | G23: CAMP4 | H23: 61.7 | I23: 7 | J23: 0 | K23: 0 | L23: 0 | M23: 0 | O23: =MONTH(B23) -> 1
A24: 3318 | B24: 45658 | C24: 55 | D24: Female | E24: North | F24: Email | H24: 36.4 | I24: 8 | J24: 0 | K24: 0 | L24: 0 | M24: 0 | O24: =MONTH(B24) -> 1
A25: 953 | B25: 45689 | C25: 20 | D25: Male | E25: North | F25: Referral | H25: 154.1 | I25: 4 | J25: 1 | K25: 289 | L25: 2 | M25: 7 | N25: 4 | O25: =MONTH(B25) -> 2
A26: 1625 | B26: 45689 | C26: 30 | D26: Female | E26: South | F26: PaidAds | G26: CAMP5 | H26: 315.3 | I26: 2 | J26: 1 | K26: 156.98 | L26: 4 | M26: 10 | N26: 3 | O26: =MONTH(B26) -> 2
A27: 1863 | B27: 45689 | C27: 44 | D27: Female | E27: South | F27: Organic | H27: 550.2 | I27: 3 | J27: 1 | K27: 38.58 | L27: 1 | M27: 12 | N27: 3 | O27: =MONTH(B27) -> 2
A28: 318 | B28: 45689 | C28: 21 | D28: Male | E28: West | F28: Organic | H28: 944.8 | I28: 8 | J28: 1 | K28: 37.2 | L28: 2 | M28: 2 | N28: 5 | O28: =MONTH(B28) -> 2
A29: 2860 | B29: 45689 | C29: 28 | D29: Male | E29: South | F29: PaidAds | G29: CAMP3 | H29: 145.8 | I29: 4 | J29: 1 | K29: 29.49 | L29: 4 | M29: 4 | N29: 4 | O29: =MONTH(B29) -> 2
A30: 3592 | B30: 45689 | C30: 31 | D30: Female | E30: South | F30: Organic | H30: 518.4 | I30: 7 | J30: 1 | K30: 24.62 | L30: 5 | M30: 11 | N30: 4 | O30: =MONTH(B30) -> 2
A31: 4420 | B31: 45689 | C31: 53 | D31: Female | E31: East | F31: Email | H31: 476.9 | I31: 6 | J31: 1 | K31: 16.76 | L31: 3 | M31: 13 | N31: 5 | O31: =MONTH(B31) -> 2
A32: 4104 | B32: 45689 | C32: 58 | D32: Female | E32: East | F32: Organic | H32: 939.6 | I32: 6 | J32: 0 | K32: 0 | L32: 0 | M32: 0 | O32: =MONTH(B32) -> 2
A33: 176 | B33: 45689 | C33: 18 | D33: Male | E33: North | F33: Referral | H33: 806.4 | I33: 5 | J33: 0 | K33: 0 | L33: 0 | M33: 0 | O33: =MONTH(B33) -> 2
A34: 240 | B34: 45689 | C34: 22 | D34: Male | E34: East | F34: Organic | H34: 770.5 | I34: 9 | J34: 0 | K34: 0 | L34: 0 | M34: 0 | O34: =MONTH(B34) -> 2
A35: 3677 | B35: 45689 | C35: 24 | D35: Female | E35: South | F35: PaidAds | G35: CAMP4 | H35: 682.3 | I35: 7 | J35: 0 | K35: 0 | L35: 0 | M35: 0 | O35: =MONTH(B35) -> 2
A36: 2173 | B36: 45689 | C36: 33 | D36: Female | E36: East | F36: Referral | H36: 509.9 | I36: 4 | J36: 0 | K36: 0 | L36: 0 | M36: 0 | O36: =MONTH(B36) -> 2
A37: 343 | B37: 45689 | C37: 21 | D37: Female | E37: North | F37: Organic | H37: 487.1 | I37: 6 | J37: 0 | K37: 0 | L37: 0 | M37: 0 | O37: =MONTH(B37) -> 2
A38: 1106 | B38: 45689 | C38: 25 | D38: Female | E38: North | F38: PaidAds | G38: CAMP2 | H38: 457.6 | I38: 5 | J38: 0 | K38: 0 | L38: 0 | M38: 0 | O38: =MONTH(B38) -> 2
A39: 1691 | B39: 45689 | C39: 26 | D39: Female | E39: West | F39: Organic | H39: 411 | I39: 4 | J39: 0 | K39: 0 | L39: 0 | M39: 0 | O39: =MONTH(B39) -> 2
A40: 4316 | B40: 45689 | C40: 52 | D40: Male | E40: South | F40: Referral | H40: 338.2 | I40: 4 | J40: 0 | K40: 0 | L40: 0 | M40: 0 | O40: =MONTH(B40) -> 2
...

Sheet Сводная таблица для А
A1: Переменная | B1: Описание | C1: Тип | T1: time_on_site_s | AH1: purchase_amount
A2: customer_id | B2: ID пользователя. | C2: целое число | K2: pages_visited | T2: =VLOOKUP(T1,$A$1:$B$15,2,0) -> сколько секунд клиент провёл на сайте. | V2: Агрегация по 60 с | AH2: =VLOOKUP(AH1,$A$1:$B$15,2,0) -> сумма покупки | AJ2: Агрегация по 50 с
A3: Date | B3: дата посещения сайта пользователем. | C3: дата (целое число) | E3: Названия строк | F3: Количество по полю satisfaction | K3: =VLOOKUP(K2,$A$1:$B$15,2,0) -> число просмотренных страниц за визит. | T3: 1 | U3: 1 | V3: 0 | W3: =SUMIFS(U:U,T:T,">="&V3,T:T,"<"&V4) -> 174 | AH3: 0 | AI3: 3180 | AJ3: 0 | AK3: =SUMIFS(AI:AI,AH:AH,">="&AJ3,AH:AH,"<"&AJ4) -> 3363
A4: age | B4: возраст пользователя | C4: целое число | E4: 2 | F4: 5 | K4: 1 | L4: 45 | T4: 4 | U4: 1 | V4: 60 | W4: =SUMIFS(U:U,T:T,">="&V4,T:T,"<"&V5) -> 539 | AH4: 1.07 | AI4: 1 | AJ4: 20 | AK4: =SUMIFS(AI:AI,AH:AH,">="&AJ4,AH:AH,"<"&AJ5) -> 465
A5: gender | B5: пол | C5: строка | E5: 3 | F5: 284 | K5: 2 | L5: 332 | T5: 9 | U5: 2 | V5: 120 | W5: =SUMIFS(U:U,T:T,">="&V5,T:T,"<"&V6) -> 620 | AH5: 1.11 | AI5: 1 | AJ5: 40 | AK5: =SUMIFS(AI:AI,AH:AH,">="&AJ5,AH:AH,"<"&AJ6) -> 375
A6: region | B6: регион проживания пользователя | C6: строка | E6: 4 | F6: 1064 | K6: 3 | L6: 1338 | T6: 10 | U6: 2 | V6: 180 | W6: =SUMIFS(U:U,T:T,">="&V6,T:T,"<"&V7) -> 579 | AH6: 7 | AI6: 1 | AJ6: 60 | AK6: =SUMIFS(AI:AI,AH:AH,">="&AJ6,AH:AH,"<"&AJ7) -> 218
A7: traffic_source | B7: источник трафика | C7: строка | E7: 5 | F7: 467 | K7: 4 | L7: 2668 | T7: 12 | U7: 1 | V7: 240 | W7: =SUMIFS(U:U,T:T,">="&V7,T:T,"<"&V8) -> 533 | AH7: 7.02 | AI7: 1 | AJ7: 80 | AK7: =SUMIFS(AI:AI,AH:AH,">="&AJ7,AH:AH,"<"&AJ8) -> 112
A8: campaign | B8: рекламная кампания | C8: строка | E8: (пусто) | K8: 5 | L8: 4290 | T8: 13 | U8: 2 | V8: 300 | W8: =SUMIFS(U:U,T:T,">="&V8,T:T,"<"&V9) -> 537 | AH8: 12 | AI8: 1 | AJ8: 100 | AK8: =SUMIFS(AI:AI,AH:AH,">="&AJ8,AH:AH,"<"&AJ9) -> 96
A9: time_on_site_s | B9: сколько секунд клиент провёл на сайте. | C9: число (с точкой) | K9: 6 | L9: 5406 | T9: 13.2 | U9: 1 | V9: 360 | W9: =SUMIFS(U:U,T:T,">="&V9,T:T,"<"&V10) -> 375 | AH9: 13 | AI9: 2 | AJ9: 120 | AK9: =SUMIFS(AI:AI,AH:AH,">="&AJ9,AH:AH,"<"&AJ10) -> 49
A10: pages_visited | B10: число просмотренных страниц за визит. | C10: целое число | K10: 7 | L10: 5152 | T10: 14 | U10: 2 | V10: 420 | W10: =SUMIFS(U:U,T:T,">="&V10,T:T,"<"&V11) -> 358 | AH10: 13.17 | AI10: 1 | AJ10: 140 | AK10: =SUMIFS(AI:AI,AH:AH,">="&AJ10,AH:AH,"<"&AJ11) -> 53
A11: converted | B11: совершил клиент покупку или нет. | C11: бинарное | K11: 8 | L11: 4304 | T11: 15 | U11: 1 | V11: 480 | W11: =SUMIFS(U:U,T:T,">="&V11,T:T,"<"&V12) -> 298 | AH11: 13.18 | AI11: 1 | AJ11: 160 | AK11: =SUMIFS(AI:AI,AH:AH,">="&AJ11,AH:AH,"<"&AJ12) -> 38
A12: purchase_amount | B12: сумма покупки | C12: число (с точкой) | K12: 9 | L12: 2709 | T12: 16 | U12: 1 | V12: 540 | W12: =SUMIFS(U:U,T:T,">="&V12,T:T,"<"&V13) -> 217 | AH12: 13.19 | AI12: 1 | AJ12: 180 | AK12: =SUMIFS(AI:AI,AH:AH,">="&AJ12,AH:AH,"<"&AJ13) -> 27
A13: num_items | B13: сколько товаров куплено в заказе | C13: целое число | K13: 10 | L13: 1910 | T13: 18 | U13: 1 | V13: 600 | W13: =SUMIFS(U:U,T:T,">="&V13,T:T,"<"&V14) -> 183 | AH13: 13.26 | AI13: 1 | AJ13: 200 | AK13: =SUMIFS(AI:AI,AH:AH,">="&AJ13,AH:AH,"<"&AJ14) -> 19
A14: delivery_time_days | B14: время доставки заказа (дни). | C14: целое число | K14: 11 | L14: 781 | T14: 20 | U14: 1 | V14: 660 | W14: =SUMIFS(U:U,T:T,">="&V14,T:T,"<"&V15) -> 123 | AH14: 13.27 | AI14: 1 | AJ14: 220 | AK14: =SUMIFS(AI:AI,AH:AH,">="&AJ14,AH:AH,"<"&AJ15) -> 15
A15: satisfaction | B15: оценка удовлетворённости клиента. | C15: целое число | K15: 12 | L15: 636 | T15: 22 | U15: 1 | V15: 720 | W15: =SUMIFS(U:U,T:T,">="&V15,T:T,"<"&V16) -> 101 | AH15: 13.34 | AI15: 1 | AJ15: 240 | AK15: =SUMIFS(AI:AI,AH:AH,">="&AJ15,AH:AH,"<"&AJ16) -> 11
K16: 13 | L16: 221 | T16: 23.7 | U16: 1 | V16: 780 | W16: =SUMIFS(U:U,T:T,">="&V16,T:T,"<"&V17) -> 78 | AH16: 13.35 | AI16: 1 | AJ16: 260 | AK16: =SUMIFS(AI:AI,AH:AH,">="&AJ16,AH:AH,"<"&AJ17) -> 13
K17: 14 | L17: 56 | T17: 24.3 | U17: 1 | V17: 840 | W17: =SUMIFS(U:U,T:T,">="&V17,T:T,"<"&V18) -> 74 | AH17: 13.38 | AI17: 1 | AJ17: 280 | AK17: =SUMIFS(AI:AI,AH:AH,">="&AJ17,AH:AH,"<"&AJ18) -> 9
K18: 15 | L18: 60 | T18: 27 | U18: 1 | V18: 900 | W18: =SUMIFS(U:U,T:T,">="&V18,T:T,"<"&V19) -> 58 | AH18: 13.41 | AI18: 1 | AJ18: 300 | AK18: =SUMIFS(AI:AI,AH:AH,">="&AJ18,AH:AH,"<"&AJ19) -> 14
K19: 16 | L19: 16 | T19: 28 | U19: 3 | V19: 960 | W19: =SUMIFS(U:U,T:T,">="&V19,T:T,"<"&V20) -> 43 | AH19: 13.47 | AI19: 1 | AJ19: 320 | AK19: =SUMIFS(AI:AI,AH:AH,">="&AJ19,AH:AH,"<"&AJ20) -> 11
K20: 18 | L20: 18 | T20: 29 | U20: 1 | V20: 1020 | W20: =SUMIFS(U:U,T:T,">="&V20,T:T,"<"&V21) -> 20 | AH20: 13.49 | AI20: 2 | AJ20: 340 | AK20: =SUMIFS(AI:AI,AH:AH,">="&AJ20,AH:AH,"<"&AJ21) -> 12
T21: 29.2 | U21: 1 | V21: 1080 | W21: =SUMIFS(U:U,T:T,">="&V21,T:T,"<"&V22) -> 19 | AH21: 13.5 | AI21: 1 | AJ21: 360 | AK21: =SUMIFS(AI:AI,AH:AH,">="&AJ21,AH:AH,"<"&AJ22) -> 9
T22: 31 | U22: 1 | V22: 1140 | W22: =SUMIFS(U:U,T:T,">="&V22,T:T,"<"&V23) -> 17 | AH22: 13.51 | AI22: 1 | AJ22: 380 | AK22: =SUMIFS(AI:AI,AH:AH,">="&AJ22,AH:AH,"<"&AJ23) -> 9
T23: 31.2 | U23: 1 | V23: 1200 | W23: =SUMIFS(U:U,T:T,">="&V23,T:T,"<"&V24) -> 10 | AH23: 13.52 | AI23: 1 | AJ23: 400 | AK23: =SUMIFS(AI:AI,AH:AH,">="&AJ23,AH:AH,"<"&AJ24) -> 8
K24: delivery_time_days | T24: 32 | U24: 1 | V24: 1260 | W24: =SUMIFS(U:U,T:T,">="&V24,T:T,"<"&V25) -> 13 | AH24: 13.56 | AI24: 2 | AJ24: 420 | AK24: =SUMIFS(AI:AI,AH:AH,">="&AJ24,AH:AH,"<"&AJ25) -> 18
K25: =VLOOKUP(K24,$A$1:$B$15,2,0) -> время доставки заказа (дни). | T25: 32.7 | U25: 1 | V25: 1320 | W25: =SUMIFS(U:U,T:T,">="&V25,T:T,"<"&V26) -> 12 | AH25: 13.68 | AI25: 1 | AJ25: 440 | AK25: =SUMIFS(AI:AI,AH:AH,">="&AJ25,AH:AH,"<"&AJ26) -> 10
K26: 0 | L26: 3180 | T26: 32.8 | U26: 1 | V26: 1380 | W26: =SUMIFS(U:U,T:T,">="&V26,T:T,"<"&V27) -> 4 | AH26: 13.77 | AI26: 1 | AJ26: 460 | AK26: =SUMIFS(AI:AI,AH:AH,">="&AJ26,AH:AH,"<"&AJ27) -> 3
K27: 1 | L27: 105 | T27: 32.9 | U27: 2 | V27: 1440 | W27: =SUMIFS(U:U,T:T,">="&V27,T:T,"<"&V28) -> 2 | AH27: 13.81 | AI27: 1 | AJ27: 480 | AK27: =SUMIFS(AI:AI,AH:AH,">="&AJ27,AH:AH,"<"&AJ28) -> 9
K28: 2 | L28: 133 | T28: 33.2 | U28: 1 | V28: 1500 | W28: =SUMIFS(U:U,T:T,">="&V28,T:T,"<"&V29) -> 3 | AH28: 13.83 | AI28: 1 | AJ28: 500 | AK28: =SUMIFS(AI:AI,AH:AH,">="&AJ28,AH:AH,"<"&AJ29) -> 9
K29: 3 | L29: 123 | T29: 33.3 | U29: 1 | V29: 1560 | W29: =SUMIFS(U:U,T:T,">="&V29,T:T,"<"&V30) -> 2 | AH29: 13.85 | AI29: 2 | AJ29: 520 | AK29: =SUMIFS(AI:AI,AH:AH,">="&AJ29,AH:AH,"<"&AJ30) -> 6
K30: 4 | L30: 127 | T30: 33.4 | U30: 1 | V30: 1620 | W30: =SUMIFS(U:U,T:T,">="&V30,T:T,"<"&V31) -> 2 | AH30: 13.86 | AI30: 1 | AJ30: 540 | AK30: =SUMIFS(AI:AI,AH:AH,">="&AJ30,AH:AH,"<"&AJ31) -> 9
K31: 5 | L31: 124 | T31: 33.9 | U31: 1 | V31: 1680 | W31: =SUMIFS(U:U,T:T,">="&V31,T:T,"<"&V32) -> 2 | AH31: 13.88 | AI31: 1 | AJ31: 560 | AK31: =SUMIFS(AI:AI,AH:AH,">="&AJ31,AH:AH,"<"&AJ32) -> 2
K32: 6 | L32: 137 | T32: 34 | U32: 2 | V32: 1740 | W32: =SUMIFS(U:U,T:T,">="&V32,T:T,"<"&V33) -> 2 | AH32: 14.18 | AI32: 1 | AJ32: 580 | AK32: =SUMIFS(AI:AI,AH:AH,">="&AJ32,AH:AH,"<"&AJ33) -> 2
K33: 7 | L33: 122 | T33: 34.5 | U33: 1 | V33: 1800 | W33: =SUMIFS(U:U,T:T,">="&V33,T:T,"<"&V34) -> 1 | AH33: 14.27 | AI33: 1 | AJ33: 600 | AK33: =SUMIFS(AI:AI,AH:AH,">="&AJ33,AH:AH,"<"&AJ34) -> 0
K34: 8 | L34: 113 | T34: 35 | U34: 1 | V34: 1860 | W34: =SUMIFS(U:U,T:T,">="&V34,T:T,"<"&V35) -> 0 | AH34: 14.34 | AI34: 1 | AJ34: 620 | AK34: =SUMIFS(AI:AI,AH:AH,">="&AJ34,AH:AH,"<"&AJ35) -> 0
K35: 9 | L35: 138 | T35: 35.1 | U35: 1 | V35: 1920 | W35: =SUMIFS(U:U,T:T,">="&V35,T:T,"<"&V36) -> 0 | AH35: 14.36 | AI35: 2 | AJ35: 640 | AK35: =SUMIFS(AI:AI,AH:AH,">="&AJ35,AH:AH,"<"&AJ36) -> 0
K36: 10 | L36: 121 | T36: 35.7 | U36: 1 | V36: 1980 | W36: =SUMIFS(U:U,T:T,">="&V36,T:T,"<"&V37) -> 0 | AH36: 14.38 | AI36: 2 | AJ36: 660 | AK36: =SUMIFS(AI:AI,AH:AH,">="&AJ36,AH:AH,"<"&AJ37) -> 0
K37: 11 | L37: 125 | T37: 35.8 | U37: 1 | V37: 2040 | W37: =SUMIFS(U:U,T:T,">="&V37,T:T,"<"&V38) -> 0 | AH37: 14.43 | AI37: 1 | AJ37: 680 | AK37: =SUMIFS(AI:AI,AH:AH,">="&AJ37,AH:AH,"<"&AJ38) -> 1
... K41: 15 | L41: 100 | T41: 36.4 | U41: 1 | V41: 2280 | W41: =SUMIFS(U:U,T:T,">="&V41,T:T,"<"&V42) -> 0 | AH41: 14.52 | AI41: 1 | AJ41: 760 | AK41: =SUMIFS(AI:AI,AH:AH,">="&AJ41,AH:AH,"<"&AJ42) -> 0
T42: 36.6 | U42: 1 | V42: 2340 | W42: =SUMIFS(U:U,T:T,">="&V42,T:T,"<"&V43) -> 0 | AH42: 14.53 | AI42: 1 | AJ42: 780 | AK42: =SUMIFS(AI:AI,AH:AH,">="&AJ42,AH:AH,"<"&AJ43) -> 0
T43: 36.7 | U43: 2 | V43: 2400 | W43: =SUMIFS(U:U,T:T,">="&V43,T:T,"<"&V44) -> 0 | AH43: 14.57 | AI43: 1 | AJ43: 800 | AK43: =SUMIFS(AI:AI,AH:AH,">="&AJ43,AH:AH,"<"&AJ44) -> 1
...

Sheet Таблицы и визуализация для А
A1: customer_id | B1: ID пользователя. | C1: целое число | E1: Дата-> | F1: Дата | G1: Заходы | I1: Период | J1: =MIN(F:F) -> 45658 | K1: =MAX(F:F) -> 45837
A2: Date | B2: дата посещения сайта пользователем. | C2: дата (целое число) | F2: 45658 | G2: 23 | I2: Среднее количество заходов на сайт за день | J2: =AVERAGE(G:G) -> 27.777778
A3: age | B3: возраст пользователя. | C3: целое число | F3: 45659 | G3: 29
A4: gender | B4: пол | C4: строка | F4: 45660 | G4: 31
A5: region | B5: регион проживания пользователя | C5: строка | F5: 45661 | G5: 26
A6: traffic_source | B6: источник трафика | C6: строка | F6: 45662 | G6: 33
A7: campaign | B7: рекламная кампания | C7: строка | F7: 45663 | G7: 24
A8: time_on_site_s | B8: сколько секунд клиент провёл на сайте. | C8: число (с точкой) | F8: 45664 | G8: 22
A9: pages_visited | B9: число просмотренных страниц за визит. | C9: целое число | F9: 45665 | G9: 38
A10: converted | B10: совершил клиент покупку или нет. | C10: бинарное | F10: 45666 | G10: 23
A11: purchase_amount | B11: сумма покупки | C11: число (с точкой) | F11: 45667 | G11: 30
A12: num_items | B12: сколько товаров куплено в заказе | C12: целое число | F12: 45668 | G12: 32
A13: delivery_time_days | B13: время доставки заказа (дни). | C13: целое число | F13: 45669 | G13: 34
A14: satisfaction | B14: оценка удовлетворённости клиента. | C14: целое число | F14: 45670 | G14: 41
F15: 45671 | G15: 31
F16: 45672 | G16: 32
F17: 45673 | G17: 32
F18: 45674 | G18: 24
F19: 45675 | G19: 20
F20: 45676 | G20: 32
F21: 45677 | G21: 25
F22: 45678 | G22: 25
F23: 45679 | G23: 36
F24: 45680 | G24: 25
F25: 45681 | G25: 30
F26: 45682 | G26: 23
... F181: 45837 | G181: 27

Sheet Бизнес анализ

Sheet CAMP
L1: customer_id | M1: campaign_n | N1: campaign
B2: Ранг | C2: Кампания | D2: Всего пользователей | E2: Покупатели | F2: Конверсия, % | G2: Ср. чек покупателей | H2: Общая выручка | I2: Cр.чек посетителей | J2: Индекс эффективности | L2: 2295 | N2: =IFERROR(VLOOKUP(M2,$A$3:$B$10,2,0),"")
A3: CAMP7 | B3: 7 | C3: CAMP7 | D3: 219 | E3: 85 | F3: 38.81 | G3: 113.58 | H3: 9654.04 | I3: 44.08 | J3: 0.92 | L3: 2903 | M3: CAMP3 | N3: =IFERROR(VLOOKUP(M3,$A$3:$B$10,2,0),"") -> 2
A4: CAMP1 | B4: 6 | C4: CAMP1 | D4: 223 | E4: 77 | F4: 34.53 | G4: 113.78 | H4: 8761.27 | I4: 39.29 | J4: 0.66 | L4: 1922 | N4: =IFERROR(VLOOKUP(M4,$A$3:$B$10,2,0),"")
A5: CAMP5 | B5: 5 | C5: CAMP5 | D5: 215 | E5: 83 | F5: 38.6 | G5: 90.79 | H5: 7535.52 | I5: 35.05 | J5: 0.62 | L5: 3627 | N5: =IFERROR(VLOOKUP(M5,$A$3:$B$10,2,0),"")
A6: CAMP6 | B6: 4 | C6: CAMP6 | D6: 205 | E6: 80 | F6: 39.02 | G6: 85.65 | H6: 6851.85 | I6: 33.42 | J6: 0.56 | L6: 2605 | N6: =IFERROR(VLOOKUP(M6,$A$3:$B$10,2,0),"")
A7: CAMP4 | B7: 3 | C7: CAMP4 | D7: 221 | E7: 70 | F7: 31.67 | G7: 108.08 | H7: 7565.65 | I7: 34.23 | J7: 0.42 | L7: 3218 | N7: =IFERROR(VLOOKUP(M7,$A$3:$B$10,2,0),"")
A8: CAMP3 | B8: 2 | C8: CAMP3 | D8: 212 | E8: 66 | F8: 31.13 | G8: 102.51 | H8: 6765.53 | I8: 31.91 | J8: 0.3 | L8: 822 | N8: =IFERROR(VLOOKUP(M8,$A$3:$B$10,2,0),"")
A9: CAMP2 | B9: 1 | C9: CAMP2 | D9: 256 | E9: 77 | F9: 30.08 | G9: 81.7 | H9: 6291.28 | I9: 24.58 | J9: 0.1 | L9: 73 | N9: =IFERROR(VLOOKUP(M9,$A$3:$B$10,2,0),"")
L10: 1902 | N10: =IFERROR(VLOOKUP(M10,$A$3:$B$10,2,0),"")
L11: 4979 | N11: =IFERROR(VLOOKUP(M11,$A$3:$B$10,2,0),"")
L12: 1427 | N12: =IFERROR(VLOOKUP(M12,$A$3:$B$10,2,0),"")
L13: 2633 | M13: CAMP5 | N13: =IFERROR(VLOOKUP(M13,$A$3:$B$10,2,0),"") -> 5
C14: вав | L14: 4777 | N14: =IFERROR(VLOOKUP(M14,$A$3:$B$10,2,0),"")
L15: 4412 | M15: CAMP3 | N15: =IFERROR(VLOOKUP(M15,$A$3:$B$10,2,0),"") -> 2
L16: 2328 | N16: =IFERROR(VLOOKUP(M16,$A$3:$B$10,2,0),"")
L17: 4152 | N17: =IFERROR(VLOOKUP(M17,$A$3:$B$10,2,0),"")
L18: 4130 | M18: CAMP2 | N18: =IFERROR(VLOOKUP(M18,$A$3:$B$10,2,0),"") -> 1
L19: 2612 | N19: =IFERROR(VLOOKUP(M19,$A$3:$B$10,2,0),"")
L20: 2912 | N20: =IFERROR(VLOOKUP(M20,$A$3:$B$10,2,0),"")
L21: 2715 | N21: =IFERROR(VLOOKUP(M21,$A$3:$B$10,2,0),"")
L22: 209 | N22: =IFERROR(VLOOKUP(M22,$A$3:$B$10,2,0),"")
L23: 4726 | M23: CAMP4 | N23: =IFERROR(VLOOKUP(M23,$A$3:$B$10,2,0),"") -> 3
L24: 3318 | N24: =IFERROR(VLOOKUP(M24,$A$3:$B$10,2,0),"")
L25: 953 | N25: =IFERROR(VLOOKUP(M25,$A$3:$B$10,2,0),"")
L26: 1625 | M26: CAMP5 | N26: =IFERROR(VLOOKUP(M26,$A$3:$B$10,2,0),"") -> 5
L27: 1863 | N27: =IFERROR(VLOOKUP(M27,$A$3:$B$10,2,0),"")
L28: 318 | N28: =IFERROR(VLOOKUP(M28,$A$3:$B$10,2,0),"")
L29: 2860 | M29: CAMP3 | N29: =IFERROR(VLOOKUP(M29,$A$3:$B$10,2,0),"") -> 2
L30: 3592 | N30: =IFERROR(VLOOKUP(M30,$A$3:$B$10,2,0),"")
L31: 4420 | N31: =IFERROR(VLOOKUP(M31,$A$3:$B$10,2,0),"")
L32: 4104 | N32: =IFERROR(VLOOKUP(M32,$A$3:$B$10,2,0),"")
L33: 176 | N33: =IFERROR(VLOOKUP(M33,$A$3:$B$10,2,0),"")
L34: 240 | N34: =IFERROR(VLOOKUP(M34,$A$3:$B$10,2,0),"")
L35: 3677 | M35: CAMP4 | N35: =IFERROR(VLOOKUP(M35,$A$3:$B$10,2,0),"") -> 3
L36: 2173 | N36: =IFERROR(VLOOKUP(M36,$A$3:$B$10,2,0),"")
L37: 343 | N37: =IFERROR(VLOOKUP(M37,$A$3:$B$10,2,0),"")
L38: 1106 | M38: CAMP2 | N38: =IFERROR(VLOOKUP(M38,$A$3:$B$10,2,0),"") -> 1
L39: 1691 | N39: =IFERROR(VLOOKUP(M39,$A$3:$B$10,2,0),"")
L40: 4316 | N40: =IFERROR(VLOOKUP(M40,$A$3:$B$10,2,0),"")
...

Sheet Трафик
B1: Ранг | C1: Трафик | D1: Всего пользователей | E1: Покупатели | F1: Конверсия, % | G1: Ср. чек покупателей | H1: Общая выручка | I1: Cр.чек посетителей | J1: Индекс эффективности
A2: Email | C2: Email | D2: 737 | E2: 269 | F2: =E2/D2 -> 0.36499322 | G2: 97.6664 | H2: 26272.25 | I2: 35.647558
A3: Organic | C3: Organic | D3: 2199 | E3: 801 | F3: =E3/D3 -> 0.36425648 | G3: 93.2508 | H3: 74693.91 | I3: 33.967217
A4: PaidAds | C4: PaidAds | D4: 1551 | E4: 538 | F4: =E4/D4 -> 0.34687299 | G4: 99.3032 | H4: 53425.14 | I4: 34.445609
A5: Referral | C5: Referral | D5: 513 | E5: 212 | F5: =E5/D5 -> 0.41325536 | G5: 95.5073 | H5: 20247.55 | I5: 39.468908
B7: Все рекламные кампании нацелены на трафик | F7: =A4 -> PaidAds

Sheet Гендер
C2: CAMP7 | E2: CAMP1 | G2: CAMP5
C3: Мужчины | D3: Женщины | E3: Мужчины | F3: Женщины | G3: Мужчины | H3: Женщины
B4: количество | C4: 110 | D4: 104 | E4: 109 | F4: 113 | G4: 99 | H4: 106
B5: конверсия | C5: 43.636364 | D5: 32.692308 | E5: 36.697248 | F5: 32.743363 | G5: 34.343434 | H5: 43.396226
B6: средний чек (покупатели) | C6: 112.265 | D6: 109.19353 | E6: 111.03075 | F6: 116.75784 | G6: 97.684118 | H6: 89.218478
B7: время на сайте | C7: 380.74 | D7: 365.39712 | E7: 409.75046 | F7: 359.57522 | G7: 380.06162 | H7: 402.11226
B8: средний чек (посетители) | C8: 6.1545455 | D8: 6 | E8: 6.0825688 | F8: 6.2035398 | G8: 5.959596 | H8: 6.2641509
B9: срреднее количество купленных позиций | C9: 2.6458333 | D9: 3 | E9: 2.825 | F9: 3.1351351 | G9: 3.0588235 | H9: 3.2826087
B16: Таблица сопряженности оценка удовлетворённости клиента. * Месяц
B17: Частота
D18: Месяц | J18: Итого
D19: январь | E19: февраль | F19: март | G19: апрель | H19: май | I19: июнь
B20: оценка удовлетворённости клиента. | C20: 2 | D20: 2 | E20: 0 | F20: 0 | G20: 2 | H20: 1 | I20: 0 | J20: 5
C21: 3 | D21: 56 | E21: 49 | F21: 45 | G21: 49 | H21: 37 | I21: 48 | J21: 284
C22: 4 | D22: 180 | E22: 168 | F22: 185 | G22: 181 | H22: 191 | I22: 159 | J22: 1064
C23: 5 | D23: 87 | E23: 64 | F23: 86 | G23: 72 | H23: 87 | I23: 71 | J23: 467
B24: Итого | D24: 325 | E24: 281 | F24: 316 | G24: 304 | H24: 316 | I24: 278 | J24: 1820
C26: NPS | D26: =D23/D24-SUM(D20:D21)/D24 -> 0.089230769 | E26: =E23/E24-SUM(E20:E21)/E24 -> 0.053380783 | F26: =F23/F24-SUM(F20:F21)/F24 -> 0.12974684 | G26: =G23/G24-SUM(G20:G21)/G24 -> 0.069078947 | H26: =H23/H24-SUM(H20:H21)/H24 -> 0.15506329 | I26: =I23/I24-SUM(I20:I21)/I24 -> 0.082733813 | J26: =J23/J24-SUM(J20:J21)/J24 -> 0.097802198

Sheet Лист7
A1: campaign | B1: purchase_amount | H1: campaign | I1: купили | J1: всего | K1: конверсия
A2: 0 | B2: 43 | E2: конверсия | F2: =I2/D3 -> 0.37170194 | H2: 0 | I2: =COUNTIFS(A:A,H2,B:B,">0") -> 1282 | J2: =COUNTIF(A:A,H2) -> 3449 | K2: =I2/J2 -> 0.37170194
A3: CAMP3 | B3: 294 | D3: =COUNTIFS(A:A,0) -> 3449 | H3: CAMP3 | I3: =COUNTIFS(A:A,H3,B:B,">0") -> 66 | J3: =COUNTIF(A:A,H3) -> 212 | K3: =I3/J3 -> 0.31132075
A4: 0 | B4: 81.55 | H4: CAMP5 | I4: =COUNTIFS(A:A,H4,B:B,">0") -> 83 | J4: =COUNTIF(A:A,H4) -> 215 | K4: =I4/J4 -> 0.38604651
A5: 0 | B5: 60.45 | H5: CAMP2 | I5: =COUNTIFS(A:A,H5,B:B,">0") -> 77 | J5: =COUNTIF(A:A,H5) -> 256 | K5: =I5/J5 -> 0.30078125
A6: 0 | B6: 45.87 | H6: CAMP4 | I6: =COUNTIFS(A:A,H6,B:B,">0") -> 70 | J6: =COUNTIF(A:A,H6) -> 221 | K6: =I6/J6 -> 0.31674208
A7: 0 | B7: 41.92 | H7: CAMP6 | I7: =COUNTIFS(A:A,H7,B:B,">0") -> 80 | J7: =COUNTIF(A:A,H7) -> 205 | K7: =I7/J7 -> 0.3902439
A8: 0 | B8: 32.4 | H8: CAMP7 | I8: =COUNTIFS(A:A,H8,B:B,">0") -> 85 | J8: =COUNTIF(A:A,H8) -> 219 | K8: =I8/J8 -> 0.38812785
A9: 0 | B9: 23.42 | H9: CAMP1 | I9: =COUNTIFS(A:A,H9,B:B,">0") -> 77 | J9: =COUNTIF(A:A,H9) -> 223 | K9: =I9/J9 -> 0.34529148
A10: 0 | B10: 23.34
A11: 0 | B11: 20.94
A12: 0 | B12: 20.31
A13: CAMP5 | B13: 0
A14: 0 | B14: 0
A15: CAMP3 | B15: 0
A16: 0 | B16: 0
A17: 0 | B17: 0
A18: CAMP2 | B18: 0
A19: 0 | B19: 0
A20: 0 | B20: 0
A21: 0 | B21: 0
A22: 0 | B22: 0
A23: CAMP4 | B23: 0
A24: 0 | B24: 0
A25: 0 | B25: 289
A26: CAMP5 | B26: 156.98
A27: 0 | B27: 38.58
A28: 0 | B28: 37.2
A29: CAMP3 | B29: 29.49
A30: 0 | B30: 24.62
A31: 0 | B31: 16.76
A32: 0 | B32: 0
A33: 0 | B33: 0
A34: 0 | B34: 0
A35: CAMP4 | B35: 0
A36: 0 | B36: 0
A37: 0 | B37: 0
A38: CAMP2 | B38: 0
A39: 0 | B39: 0
A40: 0 | B40: 0
...
